ERROR    root:services.py:282 LOGFILE - logs-upload: {'userId': '7484f34a-3acc-4ee6-8a94-fd7299502fa1', 'fileId': 'file_id', 'success': 'false', 'details': 'An error occurred (0) when calling the Unknown operation: Unknown'}
INFO     api.access:structured_logs.py:194 {'http': {'url': 'http://test.com/file/log-file/deviceid?fileId=file_id', 'request_path': '/file/log-file/deviceid', 'status_code': 400, 'method': 'POST', 'request_id': '06ca185971c24eee877ed07761fce575', 'version': '1.1'}, 'network': {'client': {'ip': '127.0.0.1', 'port': 123}}, 'duration': 15906815, 'event': '127.0.0.1:123 - "POST http://test.com/file/log-file/deviceid?fileId=file_id HTTP/1.1" 400', 'request_id': '06ca185971c24eee877ed07761fce575', 'logger': 'api.access', 'level': 'info', 'timestamp': '2025-03-31T17:39:21.767687Z'}