ERROR    root:tasks.py:85 Reencryption c1e7b1d3-fe3d-4e0f-843f-a3a2467aa745: cannot process applet d8b933be-6ec5-4418-a080-414f0871815e, skip
ERROR    root:tasks.py:86 ERROR
Traceback (most recent call last):
  File "/app/src/apps/users/tasks.py", line 67, in reencrypt_answers
    async with atomic(session):
               ~~~~~~^^^^^^^^^
  File "/app/src/apps/users/tasks.py", line 69, in reencrypt_answers
    count = await service.reencrypt_user_answers(
            ^^^^^^^^^^^^^^^^^^^^^^^^^^^^^^^^^^^^^
    ...<8 lines>...
    )
    ^
  File "/usr/local/lib/python3.13/unittest/mock.py", line 2319, in _execute_mock_call
    raise effect
Exception: ERROR
ERROR    root:tasks.py:85 Reencryption c1e7b1d3-fe3d-4e0f-843f-a3a2467aa745: cannot process applet d8b933be-6ec5-4418-a080-414f0871815e, skip
ERROR    root:tasks.py:86 ERROR
Traceback (most recent call last):
  File "/app/src/apps/users/tasks.py", line 67, in reencrypt_answers
    async with atomic(session):
               ~~~~~~^^^^^^^^^
  File "/app/src/apps/users/tasks.py", line 69, in reencrypt_answers
    count = await service.reencrypt_user_answers(
            ^^^^^^^^^^^^^^^^^^^^^^^^^^^^^^^^^^^^^
    ...<8 lines>...
    )
    ^
  File "/usr/local/lib/python3.13/unittest/mock.py", line 2319, in _execute_mock_call
    raise effect
  File "/app/src/apps/users/tasks.py", line 67, in reencrypt_answers
    async with atomic(session):
               ~~~~~~^^^^^^^^^
  File "/app/src/apps/users/tasks.py", line 69, in reencrypt_answers
    count = await service.reencrypt_user_answers(
            ^^^^^^^^^^^^^^^^^^^^^^^^^^^^^^^^^^^^^
    ...<8 lines>...
    )
    ^
  File "/usr/local/lib/python3.13/unittest/mock.py", line 2319, in _execute_mock_call
    raise effect
Exception: ERROR