INFO     root:tasks.py:25 Reencryption b0fca8b1-1d21-4faf-9a75-d660381b3b46: reencrypt_answers start
ERROR    root:tasks.py:85 Reencryption b0fca8b1-1d21-4faf-9a75-d660381b3b46: cannot process applet aa739897-3d62-418f-9d79-881ea374d4cf, skip
ERROR    root:tasks.py:86 ERROR
Traceback (most recent call last):
  File "/app/src/apps/users/tasks.py", line 67, in reencrypt_answers
    async with atomic(session):
               ~~~~~~^^^^^^^^^
  File "/app/src/apps/users/tasks.py", line 69, in reencrypt_answers
    count = await service.reencrypt_user_answers(
            ^^^^^^^^^^^^^^^^^^^^^^^^^^^^^^^^^^^^^
    ...<8 lines>...
    )
    ^
  File "/usr/local/lib/python3.13/unittest/mock.py", line 2321, in _execute_mock_call
    raise effect
Exception: ERROR