ERROR    root:tasks.py:85 Reencryption 64f580b3-690a-41e7-819f-ed9f63fd10e8: cannot process applet 1eeae7a5-1a0f-41fa-85fa-aaecae13498d, skip
ERROR    root:tasks.py:86 ERROR
Traceback (most recent call last):
  File "/app/src/apps/users/tasks.py", line 67, in reencrypt_answers
    async with atomic(session):
  File "/app/src/apps/users/tasks.py", line 69, in reencrypt_answers
    count = await service.reencrypt_user_answers(
            ^^^^^^^^^^^^^^^^^^^^^^^^^^^^^^^^^^^^^
  File "/usr/local/lib/python3.11/unittest/mock.py", line 2240, in _execute_mock_call
    raise effect
Exception: ERROR
ERROR    root:tasks.py:85 Reencryption 64f580b3-690a-41e7-819f-ed9f63fd10e8: cannot process applet 1eeae7a5-1a0f-41fa-85fa-aaecae13498d, skip
ERROR    root:tasks.py:86 ERROR
Traceback (most recent call last):
  File "/app/src/apps/users/tasks.py", line 67, in reencrypt_answers
    async with atomic(session):
  File "/app/src/apps/users/tasks.py", line 69, in reencrypt_answers
    count = await service.reencrypt_user_answers(
            ^^^^^^^^^^^^^^^^^^^^^^^^^^^^^^^^^^^^^
  File "/usr/local/lib/python3.11/unittest/mock.py", line 2240, in _execute_mock_call
    raise effect
  File "/app/src/apps/users/tasks.py", line 67, in reencrypt_answers
    async with atomic(session):
  File "/app/src/apps/users/tasks.py", line 69, in reencrypt_answers
    count = await service.reencrypt_user_answers(
            ^^^^^^^^^^^^^^^^^^^^^^^^^^^^^^^^^^^^^
  File "/usr/local/lib/python3.11/unittest/mock.py", line 2240, in _execute_mock_call
    raise effect
Exception: ERROR