ERROR    root:tasks.py:85 Reencryption 12e9eed3-9a40-4aa8-a074-5f2ca1e91947: cannot process applet 3be38bf3-f882-4882-ba85-a43a5a4e9250, skip
ERROR    root:tasks.py:86 ERROR
Traceback (most recent call last):
  File "/app/src/apps/users/tasks.py", line 67, in reencrypt_answers
    async with atomic(session):
  File "/app/src/apps/users/tasks.py", line 69, in reencrypt_answers
    count = await service.reencrypt_user_answers(
            ^^^^^^^^^^^^^^^^^^^^^^^^^^^^^^^^^^^^^
  File "/usr/local/lib/python3.11/unittest/mock.py", line 2240, in _execute_mock_call
    raise effect
Exception: ERROR