ERROR    root:tasks.py:85 Reencryption 8d39b77a-75bc-425f-93c2-8ed202dfe5fc: cannot process applet 4db38ebd-1ef0-4658-bc8c-bf1f9478b8ff, skip
ERROR    root:tasks.py:86 ERROR
Traceback (most recent call last):
  File "/app/src/apps/users/tasks.py", line 67, in reencrypt_answers
    async with atomic(session):
  File "/app/src/apps/users/tasks.py", line 69, in reencrypt_answers
    count = await service.reencrypt_user_answers(
  File "/usr/local/lib/python3.10/unittest/mock.py", line 2234, in _execute_mock_call
    raise effect
Exception: ERROR