ERROR    root:tasks.py:85 Reencryption 033b36d8-881a-4392-b1f2-dd74f186e0ea: cannot process applet 30d2f2b6-9e2a-4fb7-a60f-de3d7814cf6d, skip
ERROR    root:tasks.py:86 ERROR
Traceback (most recent call last):
  File "/app/src/apps/users/tasks.py", line 67, in reencrypt_answers
    async with atomic(session):
               ~~~~~~^^^^^^^^^
  File "/app/src/apps/users/tasks.py", line 69, in reencrypt_answers
    count = await service.reencrypt_user_answers(
            ^^^^^^^^^^^^^^^^^^^^^^^^^^^^^^^^^^^^^
    ...<8 lines>...
    )
    ^
  File "/usr/local/lib/python3.13/unittest/mock.py", line 2319, in _execute_mock_call
    raise effect
Exception: ERROR