ERROR    root:tasks.py:85 Reencryption ffd0bb36-3941-4e08-a51f-accedbcb58b6: cannot process applet a18c4ed3-ccc7-4291-aede-e5f2556661f5, skip
ERROR    root:tasks.py:86 ERROR
Traceback (most recent call last):
  File "/app/src/apps/users/tasks.py", line 67, in reencrypt_answers
    async with atomic(session):
  File "/app/src/apps/users/tasks.py", line 69, in reencrypt_answers
    count = await service.reencrypt_user_answers(
  File "/usr/local/lib/python3.10/unittest/mock.py", line 2234, in _execute_mock_call
    raise effect
Exception: ERROR