ERROR    root:tasks.py:85 Reencryption b12f9431-cfcc-4030-97f6-f3804055cc68: cannot process applet 494ca824-12e5-4880-98a8-5fd4263d5ba3, skip
ERROR    root:tasks.py:86 ERROR
Traceback (most recent call last):
  File "/app/src/apps/users/tasks.py", line 67, in reencrypt_answers
    async with atomic(session):
  File "/app/src/apps/users/tasks.py", line 69, in reencrypt_answers
    count = await service.reencrypt_user_answers(
  File "/usr/local/lib/python3.10/unittest/mock.py", line 2234, in _execute_mock_call
    raise effect
Exception: ERROR
ERROR    root:tasks.py:85 Reencryption b12f9431-cfcc-4030-97f6-f3804055cc68: cannot process applet 494ca824-12e5-4880-98a8-5fd4263d5ba3, skip
ERROR    root:tasks.py:86 ERROR
Traceback (most recent call last):
  File "/app/src/apps/users/tasks.py", line 67, in reencrypt_answers
    async with atomic(session):
  File "/app/src/apps/users/tasks.py", line 69, in reencrypt_answers
    count = await service.reencrypt_user_answers(
  File "/usr/local/lib/python3.10/unittest/mock.py", line 2234, in _execute_mock_call
    raise effect
  File "/app/src/apps/users/tasks.py", line 67, in reencrypt_answers
    async with atomic(session):
  File "/app/src/apps/users/tasks.py", line 69, in reencrypt_answers
    count = await service.reencrypt_user_answers(
  File "/usr/local/lib/python3.10/unittest/mock.py", line 2234, in _execute_mock_call
    raise effect
Exception: ERROR