ERROR    root:tasks.py:85 Reencryption 960ac7cc-5b6b-4140-bc64-2158f1cf0f3b: cannot process applet 733c062a-f646-4f7d-a8a6-02fb1856a2e9, skip
ERROR    root:tasks.py:86 ERROR
Traceback (most recent call last):
  File "/app/src/apps/users/tasks.py", line 67, in reencrypt_answers
    async with atomic(session):
  File "/app/src/apps/users/tasks.py", line 69, in reencrypt_answers
    count = await service.reencrypt_user_answers(
  File "/usr/local/lib/python3.10/unittest/mock.py", line 2234, in _execute_mock_call
    raise effect
Exception: ERROR