INFO     root:tasks.py:25 Reencryption d187ec11-1193-41a3-9560-9d5bcf13bf00: reencrypt_answers start
ERROR    root:tasks.py:85 Reencryption d187ec11-1193-41a3-9560-9d5bcf13bf00: cannot process applet 2634205d-6a23-4f1f-bde7-cc552624bcce, skip
ERROR    root:tasks.py:86 ERROR
Traceback (most recent call last):
  File "/app/src/apps/users/tasks.py", line 67, in reencrypt_answers
    async with atomic(session):
               ~~~~~~^^^^^^^^^
  File "/app/src/apps/users/tasks.py", line 69, in reencrypt_answers
    count = await service.reencrypt_user_answers(
            ^^^^^^^^^^^^^^^^^^^^^^^^^^^^^^^^^^^^^
    ...<8 lines>...
    )
    ^
  File "/usr/local/lib/python3.13/unittest/mock.py", line 2321, in _execute_mock_call
    raise effect
Exception: ERROR