ERROR    root:tasks.py:85 Reencryption 37c024f2-4254-4c67-a2da-bee399487d82: cannot process applet a6cea611-85a4-4fe1-80e8-73c220c56df4, skip
ERROR    root:tasks.py:86 ERROR
Traceback (most recent call last):
  File "/app/src/apps/users/tasks.py", line 67, in reencrypt_answers
    async with atomic(session):
  File "/app/src/apps/users/tasks.py", line 69, in reencrypt_answers
    count = await service.reencrypt_user_answers(
  File "/usr/local/lib/python3.10/unittest/mock.py", line 2234, in _execute_mock_call
    raise effect
Exception: ERROR