ERROR    root:tasks.py:85 Reencryption cd4137fe-174e-49a9-8e5d-4aacf6cef1f3: cannot process applet e8f157f4-8bd8-4075-930b-39b635673eed, skip
ERROR    root:tasks.py:86 ERROR
Traceback (most recent call last):
  File "/app/src/apps/users/tasks.py", line 67, in reencrypt_answers
    async with atomic(session):
               ~~~~~~^^^^^^^^^
  File "/app/src/apps/users/tasks.py", line 69, in reencrypt_answers
    count = await service.reencrypt_user_answers(
            ^^^^^^^^^^^^^^^^^^^^^^^^^^^^^^^^^^^^^
    ...<8 lines>...
    )
    ^
  File "/usr/local/lib/python3.13/unittest/mock.py", line 2319, in _execute_mock_call
    raise effect
Exception: ERROR
ERROR    root:tasks.py:85 Reencryption cd4137fe-174e-49a9-8e5d-4aacf6cef1f3: cannot process applet e8f157f4-8bd8-4075-930b-39b635673eed, skip
ERROR    root:tasks.py:86 ERROR
Traceback (most recent call last):
  File "/app/src/apps/users/tasks.py", line 67, in reencrypt_answers
    async with atomic(session):
               ~~~~~~^^^^^^^^^
  File "/app/src/apps/users/tasks.py", line 69, in reencrypt_answers
    count = await service.reencrypt_user_answers(
            ^^^^^^^^^^^^^^^^^^^^^^^^^^^^^^^^^^^^^
    ...<8 lines>...
    )
    ^
  File "/usr/local/lib/python3.13/unittest/mock.py", line 2319, in _execute_mock_call
    raise effect
  File "/app/src/apps/users/tasks.py", line 67, in reencrypt_answers
    async with atomic(session):
               ~~~~~~^^^^^^^^^
  File "/app/src/apps/users/tasks.py", line 69, in reencrypt_answers
    count = await service.reencrypt_user_answers(
            ^^^^^^^^^^^^^^^^^^^^^^^^^^^^^^^^^^^^^
    ...<8 lines>...
    )
    ^
  File "/usr/local/lib/python3.13/unittest/mock.py", line 2319, in _execute_mock_call
    raise effect
Exception: ERROR