ERROR    root:tasks.py:85 Reencryption f47be2be-753e-4f2b-b0cb-e2df49d71938: cannot process applet 6c78f023-f957-48fa-bd94-3167bb3456dc, skip
ERROR    root:tasks.py:86 ERROR
Traceback (most recent call last):
  File "/app/src/apps/users/tasks.py", line 67, in reencrypt_answers
    async with atomic(session):
  File "/app/src/apps/users/tasks.py", line 69, in reencrypt_answers
    count = await service.reencrypt_user_answers(
  File "/usr/local/lib/python3.10/unittest/mock.py", line 2234, in _execute_mock_call
    raise effect
Exception: ERROR