ERROR    root:tasks.py:85 Reencryption dcfcb3da-f5c6-4aef-84a7-f7fbee2b5f12: cannot process applet 1373cb77-2349-4011-bd49-41960150d70c, skip
ERROR    root:tasks.py:86 ERROR
Traceback (most recent call last):
  File "/app/src/apps/users/tasks.py", line 67, in reencrypt_answers
    async with atomic(session):
  File "/app/src/apps/users/tasks.py", line 69, in reencrypt_answers
    count = await service.reencrypt_user_answers(
  File "/usr/local/lib/python3.10/unittest/mock.py", line 2234, in _execute_mock_call
    raise effect
Exception: ERROR