ERROR    root:tasks.py:85 Reencryption 0273771c-2bf1-4f9d-b543-55c5fe51326c: cannot process applet 7d871b63-5f5e-4cab-bd87-f033ed02b087, skip
ERROR    root:tasks.py:86 ERROR
Traceback (most recent call last):
  File "/app/src/apps/users/tasks.py", line 67, in reencrypt_answers
    async with atomic(session):
  File "/app/src/apps/users/tasks.py", line 69, in reencrypt_answers
    count = await service.reencrypt_user_answers(
            ^^^^^^^^^^^^^^^^^^^^^^^^^^^^^^^^^^^^^
  File "/usr/local/lib/python3.11/unittest/mock.py", line 2240, in _execute_mock_call
    raise effect
Exception: ERROR
ERROR    root:tasks.py:85 Reencryption 0273771c-2bf1-4f9d-b543-55c5fe51326c: cannot process applet 7d871b63-5f5e-4cab-bd87-f033ed02b087, skip
ERROR    root:tasks.py:86 ERROR
Traceback (most recent call last):
  File "/app/src/apps/users/tasks.py", line 67, in reencrypt_answers
    async with atomic(session):
  File "/app/src/apps/users/tasks.py", line 69, in reencrypt_answers
    count = await service.reencrypt_user_answers(
            ^^^^^^^^^^^^^^^^^^^^^^^^^^^^^^^^^^^^^
  File "/usr/local/lib/python3.11/unittest/mock.py", line 2240, in _execute_mock_call
    raise effect
  File "/app/src/apps/users/tasks.py", line 67, in reencrypt_answers
    async with atomic(session):
  File "/app/src/apps/users/tasks.py", line 69, in reencrypt_answers
    count = await service.reencrypt_user_answers(
            ^^^^^^^^^^^^^^^^^^^^^^^^^^^^^^^^^^^^^
  File "/usr/local/lib/python3.11/unittest/mock.py", line 2240, in _execute_mock_call
    raise effect
Exception: ERROR