ERROR    root:tasks.py:85 Reencryption 2c1a1ea1-b04e-4169-add9-9f758beb4a4e: cannot process applet 494b8a8d-115b-4496-82cd-833f489c5d2b, skip
ERROR    root:tasks.py:86 ERROR
Traceback (most recent call last):
  File "/app/src/apps/users/tasks.py", line 67, in reencrypt_answers
    async with atomic(session):
  File "/app/src/apps/users/tasks.py", line 69, in reencrypt_answers
    count = await service.reencrypt_user_answers(
  File "/usr/local/lib/python3.10/unittest/mock.py", line 2234, in _execute_mock_call
    raise effect
Exception: ERROR